Workbook
Name PRINT_AREA_MI: #REF!

Sheet Indices_Margins
A1: Index
C2: January | D2: February | E2: March | F2: April | G2: May | H2: June | I2: July | J2: August | K2: September | L2: October | M2: November | N2: December
A3: NEW BUY INDEX
A4: input from CAP | B4: 2025 | C4: 1 | D4: 1 | E4: 1 | F4: 1 | G4: 1 | H4: 1 | I4: 1 | J4: 1 | K4: 1 | L4: 1 | M4: 1 | N4: 1 | O4: =SUM(C4:N4) -> 12
A5: calculation | C5: =C4/$O$4 -> 0.083333333 | D5: =D4/$O$4 -> 0.083333333 | E5: =E4/$O$4 -> 0.083333333 | F5: =F4/$O$4 -> 0.083333333 | G5: =G4/$O$4 -> 0.083333333 | H5: =H4/$O$4 -> 0.083333333 | I5: =I4/$O$4 -> 0.083333333 | J5: =J4/$O$4 -> 0.083333333 | ... N5: =N4/$O$4 -> 0.083333333 | O5: =SUM(C5:N5) -> 1
A6: input from CAP | B6: 2024 | C6: 1 | D6: 1 | E6: 618.22 | F6: 1.94 | G6: 1 | H6: 1 | I6: 1 | J6: 1 | K6: 1 | L6: 1 | M6: 1 | N6: 1 | O6: =SUM(C6:N6) -> 630.16
A7: calculation | C7: =C6/$O$6 -> 0.0015868986 | D7: =D6/$O$6 -> 0.0015868986 | E7: =E6/$O$6 -> 0.98105243 | F7: =F6/$O$6 -> 0.0030785832 | G7: =G6/$O$6 -> 0.0015868986 | H7: =H6/$O$6 -> 0.0015868986 | I7: =I6/$O$6 -> 0.0015868986 | J7: =J6/$O$6 -> 0.0015868986 | ... N7: =N6/$O$6 -> 0.0015868986 | O7: =SUM(C7:N7) -> 1
C9: =(C5+C7)/2 -> 0.042460116 | D9: =(D5+D7)/2 -> 0.042460116 | E9: =(E5+E7)/2 -> 0.53219288 | F9: =(F5+F7)/2 -> 0.043205958 | G9: =(G5+G7)/2 -> 0.042460116 | H9: =(H5+H7)/2 -> 0.042460116 | I9: =(I5+I7)/2 -> 0.042460116 | J9: =(J5+J7)/2 -> 0.042460116 | ... N9: =(N5+N7)/2 -> 0.042460116 | O9: =SUM(C9:N9) -> 1
A11: USED BUY INDEX
A12: input from CAP | B12: 2025 | C12: 52154.11 | D12: 30951.46 | E12: 38954.98 | F12: 44995.46 | G12: 55332.9 | H12: 38854.87 | I12: 44246.87 | J12: 61285.45 | K12: 38490.74 | L12: 39954.28 | M12: 39894 | N12: 43954.02 | O12: =SUM(C12:N12) -> 529069.14
A13: calculation | C13: =C12/$O$12 -> 0.098577116 | D13: =D12/$O$12 -> 0.05850173 | E13: =E12/$O$12 -> 0.07362928 | F13: =F12/$O$12 -> 0.085046465 | G13: =G12/$O$12 -> 0.10458539 | H13: =H12/$O$12 -> 0.073440061 | I13: =I12/$O$12 -> 0.083631546 | J13: =J12/$O$12 -> 0.11583637 | ... N13: =N12/$O$12 -> 0.083078026 | O13: =SUM(C13:N13) -> 1
A14: input from CAP | B14: 2024 | C14: 40907.88 | D14: 41173.07 | E14: 37793.75 | F14: 49429.05 | G14: 57243.76 | H14: 46187.96 | I14: 53377.54 | J14: 64187.11 | K14: 33462.55 | L14: 38348.98 | M14: 41165.58 | N14: 48368.8 | O14: =SUM(C14:N14) -> 551646.03
A15: calculation | C15: =C14/$O$14 -> 0.074156031 | D15: =D14/$O$14 -> 0.074636756 | E15: =E14/$O$14 -> 0.068510871 | F15: =F14/$O$14 -> 0.089602838 | G15: =G14/$O$14 -> 0.10376901 | H15: =H14/$O$14 -> 0.083727531 | I15: =I14/$O$14 -> 0.09676049 | J15: =J14/$O$14 -> 0.11635561 | ... N15: =N14/$O$14 -> 0.087680863 | O15: =SUM(C15:N15) -> 1
C17: =(C13+C15)/2 -> 0.086366573 | D17: =(D13+D15)/2 -> 0.066569243 | E17: =(E13+E15)/2 -> 0.071070076 | F17: =(F13+F15)/2 -> 0.087324652 | G17: =(G13+G15)/2 -> 0.1041772 | H17: =(H13+H15)/2 -> 0.078583796 | I17: =(I13+I15)/2 -> 0.090196018 | J17: =(J13+J15)/2 -> 0.11609599 | ... N17: =(N13+N15)/2 -> 0.085379445 | O17: =SUM(C17:N17) -> 1
A19: COMBINED SALES INDEX
A20: input from CAP | B20: 2025 | C20: 89797.23 | D20: 94694.78 | E20: 129984.15 | F20: 109322.38 | G20: 130991.68 | H20: 128556.74 | I20: 127924.41 | J20: 193654.06 | K20: 109375.01 | L20: 120976.64 | M20: 119785.36 | N20: 100405.6 | O20: =SUM(C20:N20) -> 1455468
A21: calculation | C21: =C20/$O$20 -> 0.061696463 | D21: =D20/$O$20 -> 0.065061394 | E21: =E20/$O$20 -> 0.089307457 | F21: =F20/$O$20 -> 0.075111495 | G21: =G20/$O$20 -> 0.089999695 | H21: =H20/$O$20 -> 0.088326735 | I21: =I20/$O$20 -> 0.087892284 | J21: =J20/$O$20 -> 0.13305277 | ... N21: =N20/$O$20 -> 0.068985094 | O21: =SUM(C21:N21) -> 1
A22: input from CAP | B22: 2024 | C22: 82139.67 | D22: 118364.87 | E22: 127366.77 | F22: 126296.59 | G22: 143860.31 | H22: 122501.21 | I22: 120254.83 | J22: 191102.12 | K22: 121687.93 | L22: 123451.05 | M22: 117125.06 | N22: 113865.72 | O22: =SUM(C22:N22) -> 1508016.1
A23: calculation | C23: =C22/$O$22 -> 0.054468695 | D23: =D22/$O$22 -> 0.078490454 | E23: =E22/$O$22 -> 0.084459819 | F23: =F22/$O$22 -> 0.083750159 | G23: =G22/$O$22 -> 0.095397063 | H23: =H22/$O$22 -> 0.081233355 | I23: =I22/$O$22 -> 0.079743729 | J23: =J22/$O$22 -> 0.12672419 | ... N23: =N22/$O$22 -> 0.075506964 | O23: =SUM(C23:N23) -> 1
C25: =(C21+C23)/2 -> 0.058082579 | D25: =(D21+D23)/2 -> 0.071775924 | E25: =(E21+E23)/2 -> 0.086883638 | F25: =(F21+F23)/2 -> 0.079430827 | G25: =(G21+G23)/2 -> 0.092698379 | H25: =(H21+H23)/2 -> 0.084780045 | I25: =(I21+I23)/2 -> 0.083818007 | J25: =(J21+J23)/2 -> 0.12988848 | ... N25: =(N21+N23)/2 -> 0.072246029 | O25: =SUM(C25:N25) -> 1
C27: New Buys | D27: Used Buys | E27: New Sales
C28: =C9 -> 0.042460116 | D28: =C17 -> 0.086366573 | E28: =C25 -> 0.058082579
C29: =D9 -> 0.042460116 | D29: =+D17 -> 0.066569243 | E29: =D25 -> 0.071775924
C30: =E9 -> 0.53219288 | D30: =E17 -> 0.071070076 | E30: =E25 -> 0.086883638
C31: =F9 -> 0.043205958 | D31: =F17 -> 0.087324652 | E31: =F25 -> 0.079430827
C32: =G9 -> 0.042460116 | D32: =G17 -> 0.1041772 | E32: =G25 -> 0.092698379
C33: =H9 -> 0.042460116 | D33: =H17 -> 0.078583796 | E33: =H25 -> 0.084780045
C34: =I9 -> 0.042460116 | D34: =I17 -> 0.090196018 | E34: =I25 -> 0.083818007
C35: =J9 -> 0.042460116 | D35: =J17 -> 0.11609599 | E35: =J25 -> 0.12988848
C36: =K9 -> 0.042460116 | D36: =K17 -> 0.066705637 | E36: =K25 -> 0.077920853
C37: =L9 -> 0.042460116 | D37: =L17 -> 0.072517719 | E37: =L25 -> 0.082490968
C38: =M9 -> 0.042460116 | D38: =M17 -> 0.075013656 | E38: =M25 -> 0.07998427
C39: =N9 -> 0.042460116 | D39: =N17 -> 0.085379445 | E39: =N25 -> 0.072246029
C40: =O9 -> 1 | D40: =O17 -> 1 | E40: =O25 -> 1
A42: Margins
C43: =C2 -> January | D43: =D2 -> February | E43: =E2 -> March | F43: =F2 -> April | G43: =G2 -> May | H43: =H2 -> June | I43: =I2 -> July | J43: =J2 -> August | ... N43: =N2 -> December
A44: USED GPM%
A45: GPM% from CAP | B45: 2025 | C45: 0.614265 | D45: 0.668535 | E45: 0.667395 | F45: 0.624424 | G45: 0.672216 | H45: 0.625265 | I45: 0.669767 | J45: 0.665646 | K45: 0.629033 | L45: 0.655925 | M45: 0.657312 | N45: 0.6544
A46: Sales from CAP | B46: sales | C46: 89775.82 | D46: 94616.03 | E46: 129918.15 | F46: 109231.47 | G46: 130864.57 | H46: 128537.74 | I46: 127686.9 | J46: 193175.05 | K46: 109082.58 | L46: 120536.55 | M46: 119098.78 | N46: 100232.08
A47: GPM% from CAP | B47: 2024 | C47: 0.611884 | D47: 0.643635 | E47: 0.659906 | F47: 0.646692 | G47: 0.671222 | H47: 0.651208 | I47: 0.673464 | J47: 0.652391 | K47: 0.662877 | L47: 0.66043 | M47: 0.664451 | N47: 0.657062
...

Sheet Input
A2: Yellow Denotes User Input, Omit % and $ Signs
A3: Grey Denotes Calculation
A4: STORE INFORMATION | J4: EXPENSE SUMMARY (Monthly Estimates, except where a percent of sales)
A6: FRANCHISEE NAME | C6: Bob, Lori & Adam Brown | J6: HOURLY LABOR COST | L6: (annual Yr 1 - Yr 2) | M6: =T21 -> 0 | N6: =V21 -> 0 | O6: (as calculated below) | Q6: INSURANCE-BUSINESS | T6: 741 | U6: ($ per month)
A7: STORE LOCATION | C7: Ann Arbor | J7: PAYROLL TAXES | M7: 0.09 | P7: (% of payroll) | Q7: EMPLOY. HEALTH INS. | T7: 527 | U7: ($ per month)
A8: STORE # | C8: 80726 | J8: PAYROLL SERVICES | L8: with workers comp | P8: ($ per month)
A9: Plan Start Date (month-day-year) | C9: 44561 | J9: WORKERS COMP INS | M9: 0.002 | P9: (% of payroll) | Q9: OUTSIDE SERVICES | U9: ($ per month)
A10: OWNER'S NAME | C10: Bob, Lori & Adam Brown | Q10: STORE OPERATING EXPENSE | T10: 925 | U10: ($ per month)
J11: ADVERTISING | M11: 0.055 | P11: (% of sales) | Q11: MISC EXPENSE | U11: ($ per month)
A12: ESTIMATED SALES | C12: (enter Total and Used %) | F12: Used | H12: New | J12: ACCOUNTING FEES | P12: ($ per month)
C13: Total | F13: % | G13: $ | H13: % | I13: $ | J13: ROYALTY | M13: 0.05 | P13: (% of sales)
B14: YEAR 1 | C14: 1550000 | F14: 0.99 | G14: =C14*F14 -> 1534500 | H14: =1-F14 -> 0.01 | I14: =H14*C14 -> 15500 | J14: BANK/CREDIT CARD CHARGES | P14: (% of sales)
B15: YEAR 2 | C15: =C14*(1+D15) -> 1643000 | D15: 0.06 | E15: % increase | F15: 0.99 | G15: =C15*F15 -> 1626570 | H15: =1-F15 -> 0.01 | I15: =H15*C15 -> 16430 | J15: CHECK GUARANTEE | P15: (% of sales) | Q15: Labor Cost Calculation
B16: YEAR 3 ASSUMPTIONS | C16: =C15*(1+D16) -> 1741580 | D16: 0.06 | E16: % increase | F16: 0.99 | G16: =C16*F16 -> 1724164.2 | H16: =1-F16 -> 0.01 | I16: =H16*C16 -> 17415.8 | Q16: (Based on Sales estimate - to be allocated by sales index; includes manager hours and base pay)
J17: RENT (Monthly: Base + CAM) | M17: 15800 | P17: ($ per month)
A18: MANAGEMENT COMPENSATION: | J18: SECURITY MONITORING | M18: 60 | P18: ($ per month) | Q18: Percentage of sales method | T18: Year 1 | V18: Year 2
C19: OWNER | J19: LEASING PAYMENT | P19: ($ per month) | Q19: Hourly labor percent of sales
C20: Salary | Q20: (does not include payroll taxes)
B21: YEAR 1 | C21: 0 | J21: REPAIRS / MAINTANENCE | M21: 269 | P21: ($ per month) | Q21: Total hourly labor expense | S21: (calculated) | T21: =T19*C14 -> 0 | V21: =V19*C15 -> 0
B22: YEAR 2 | C22: 0 | J22: BUS. TRAVEL/ENTERTAIN. | M22: 309 | P22: ($ per month)
J23: BUSINESS VEHICLE | M23: 476 | P23: ($ per month) | Q23: Additional (optional) labor information
Q24: Average hourly rate | S24: (input)
C25: MANAGER | J25: OFFICE SUPPLIES & EXP | M25: 0.02 | P25: (% of sales) | Q25: Estimated labor expense | S25: (calculated) | T25: =T21 -> 0 | V25: =V21 -> 0
C26: Salary | E26: Bonus (if $) | G26: Bonus (if % of sales) | J26: CELL PHONE | M26: 108 | P26: ($ per month) | Q26: Estimated hours | S26: (calculated) | T26: =T25/T24 -> #DIV/0! | V26: =V25/V24 -> #DIV/0!
B27: YEAR 1 | C27: 60000 | J27: TELEPHONE/INTERNET | M27: 339 | P27: ($ per month) | Q27: Annual Manager Floor Hours* | S27: (input)
B28: YEAR 2 | C28: 60000 | J28: UTILITIES | M28: 812 | P28: ($ per month) | R28: (New stores: Estimate 40 hours per week per operating partner)
Q29: Estimated sales per labor hour | S29: (calculated) | T29: =C14/(T26+T27) -> #DIV/0! | V29: =C15/(V26+V27) -> #DIV/0!
A31: Balance Sheet Summary
L32: Inventory Profile (all amounts need to be filled in)
A33: CASH BALANCE DAY ONE OF PLAN | E33: 42000
S34: Sales and Buy Indexes
A35: Debt Summary
L36: YEAR 1 | S36: Month | T36: Sales Index | V36: NEW Buys Index | X36: USED Buys Index
A37: FINANCING-loan #1 | E37: Credit Card Summary | P37: Actual | Q37: Target | R37: 1 | S37: January | T37: =Indices_Margins!C25 -> 0.058082579 | V37: =Indices_Margins!C28 -> 0.042460116 | X37: =Indices_Margins!C17 -> 0.086366573
A38: Original Balance | F38: (Visa/MC/Other) | L38: INVENTORY - NEW | P38: 26 | Q38: ='P&LY1'!O20/Input!P45 -> 1413.1281 | R38: 2 | S38: February | T38: =Indices_Margins!D25 -> 0.071775924 | V38: =Indices_Margins!C29 -> 0.042460116 | X38: =Indices_Margins!D17 -> 0.066569243
A39: Interest Rate | R39: 3 | S39: March | T39: =Indices_Margins!E25 -> 0.086883638 | V39: =Indices_Margins!C30 -> 0.53219288 | X39: =Indices_Margins!E17 -> 0.071070076
A40: Term (years) | E40: Current Balance | L40: INVENTORY - USED | P40: 98250 | Q40: ='P&LY1'!O16/Input!P47 -> 106189.78 | R40: 4 | S40: April | T40: =Indices_Margins!F25 -> 0.079430827 | V40: =Indices_Margins!C31 -> 0.043205958 | X40: =Indices_Margins!F17 -> 0.087324652
A41: Calculated Payment | C41: =IF(C38=0,0,PMT(C39/12,C40*12,-C38)) -> 0 | E41: Interest Rate | R41: 5 | S41: May | T41: =Indices_Margins!G25 -> 0.092698379 | V41: =Indices_Margins!C32 -> 0.042460116 | X41: =Indices_Margins!G17 -> 0.1041772
A42: Current Outstanding Balance | L42: Freight | P42: 0 | Q42: (% of new sales) | R42: 6 | S42: June | T42: =Indices_Margins!H25 -> 0.084780045 | V42: =Indices_Margins!C33 -> 0.042460116 | X42: =Indices_Margins!H17 -> 0.078583796
A43: *Notes | B43: Loan to be paid off at the end of Oct | E43: Principal Payments (reductions) | L43: Inventory Shrink | P43: 0.0125 | Q43: (% of total sales) | R43: 7 | S43: July | T43: =Indices_Margins!I25 -> 0.083818007 | V43: =Indices_Margins!C34 -> 0.042460116 | X43: =Indices_Margins!I17 -> 0.090196018
...

Sheet P&LY1
A2: =Input!C6 -> Bob, Lori & Adam Brown
A3: =Input!C9 -> 44561
A4: =Input!C7 -> Ann Arbor
A6: MONTH | C6: =Input!C9 -> 44561 | D6: =DATE(YEAR(C6),MONTH(C6)+1,DAY(C6)) -> 44592 | E6: =DATE(YEAR(D6),MONTH(D6)+1,DAY(D6)) -> 44620 | F6: =DATE(YEAR(E6),MONTH(E6)+1,DAY(E6)) -> 44651 | G6: =DATE(YEAR(F6),MONTH(F6)+1,DAY(F6)) -> 44681 | H6: =DATE(YEAR(G6),MONTH(G6)+1,DAY(G6)) -> 44712 | I6: =DATE(YEAR(H6),MONTH(H6)+1,DAY(H6)) -> 44742 | J6: =DATE(YEAR(I6),MONTH(I6)+1,DAY(I6)) -> 44773 | K6: =DATE(YEAR(J6),MONTH(J6)+1,DAY(J6)) -> 44804 | ... N6: =DATE(YEAR(M6),MONTH(M6)+1,DAY(M6)) -> 44895 | O6: Total
A8: Sales Index | C8: =VLOOKUP(MONTH(C6),Input!$R$37:$X$48,3) -> 0.058082579 | D8: =VLOOKUP(MONTH(D6),Input!$R$37:$X$48,3) -> 0.071775924 | E8: =VLOOKUP(MONTH(E6),Input!$R$37:$X$48,3) -> 0.086883638 | F8: =VLOOKUP(MONTH(F6),Input!$R$37:$X$48,3) -> 0.079430827 | G8: =VLOOKUP(MONTH(G6),Input!$R$37:$X$48,3) -> 0.092698379 | H8: =VLOOKUP(MONTH(H6),Input!$R$37:$X$48,3) -> 0.084780045 | I8: =VLOOKUP(MONTH(I6),Input!$R$37:$X$48,3) -> 0.083818007 | J8: =VLOOKUP(MONTH(J6),Input!$R$37:$X$48,3) -> 0.12988848 | ... N8: =VLOOKUP(MONTH(N6),Input!$R$37:$X$48,3) -> 0.072246029 | O8: =SUM(C8:N8) -> 1
A10: SALES-Used | C10: =C8*Input!$G$14 -> 89127.717 | D10: =D8*Input!$G$14 -> 110140.16 | E10: =E8*Input!$G$14 -> 133322.94 | F10: =F8*Input!$G$14 -> 121886.6 | G10: =G8*Input!$G$14 -> 142245.66 | H10: =H8*Input!$G$14 -> 130094.98 | I10: =I8*Input!$G$14 -> 128618.73 | J10: =J8*Input!$G$14 -> 199313.87 | ... N10: =N8*Input!$G$14 -> 110861.53 | O10: =SUM(C10:N10) -> 1534500 | P10: =O10/$O$12 -> 0.99
A11: SALES-New | C11: =C8*Input!$I$14 -> 900.27997 | D11: =D8*Input!$I$14 -> 1112.5268 | E11: =E8*Input!$I$14 -> 1346.6964 | F11: =F8*Input!$I$14 -> 1231.1778 | G11: =G8*Input!$I$14 -> 1436.8249 | H11: =H8*Input!$I$14 -> 1314.0907 | I11: =I8*Input!$I$14 -> 1299.1791 | J11: =J8*Input!$I$14 -> 2013.2715 | ... N11: =N8*Input!$I$14 -> 1119.8135 | O11: =SUM(C11:N11) -> 15500 | P11: =O11/$O$12 -> 0.01
A12: Total Sales | C12: =SUM(C10:C11) -> 90027.997 | D12: =SUM(D10:D11) -> 111252.68 | E12: =SUM(E10:E11) -> 134669.64 | F12: =SUM(F10:F11) -> 123117.78 | G12: =SUM(G10:G11) -> 143682.49 | H12: =SUM(H10:H11) -> 131409.07 | I12: =SUM(I10:I11) -> 129917.91 | J12: =SUM(J10:J11) -> 201327.15 | ... N12: =SUM(N10:N11) -> 111981.35 | O12: =SUM(C12:N12) -> 1550000 | P12: =O12/$O$12 -> 1
A14: COST OF SALES
A15: Used GPM% | C15: =VLOOKUP(MONTH(C6),Input!$R$53:$V$64,3) -> 0.61313072 | D15: =VLOOKUP(MONTH(D6),Input!$R$53:$V$64,3) -> 0.65472673 | E15: =VLOOKUP(MONTH(E6),Input!$R$53:$V$64,3) -> 0.66369634 | F15: =VLOOKUP(MONTH(F6),Input!$R$53:$V$64,3) -> 0.63631595 | G15: =VLOOKUP(MONTH(G6),Input!$R$53:$V$64,3) -> 0.67169609 | H15: =VLOOKUP(MONTH(H6),Input!$R$53:$V$64,3) -> 0.63791521 | I15: =VLOOKUP(MONTH(I6),Input!$R$53:$V$64,3) -> 0.67155953 | J15: =VLOOKUP(MONTH(J6),Input!$R$53:$V$64,3) -> 0.65905588 | ... N15: =VLOOKUP(MONTH(N6),Input!$R$53:$V$64,3) -> 0.65581541
A16: Cost of Goods Sold-Used | C16: =C10*(1-C15) -> 34480.776 | D16: =D10*(1-D15) -> 38028.451 | E16: =E10*(1-E15) -> 44836.993 | F16: =F10*(1-F15) -> 44328.213 | G16: =G10*(1-G15) -> 46699.807 | H16: =H10*(1-H15) -> 47105.414 | I16: =I10*(1-I15) -> 42243.596 | J16: =J10*(1-J15) -> 67954.893 | ... N16: =N10*(1-N15) -> 38156.83 | O16: =SUM(C16:N16) -> 530948.9 | P16: =O16/$O$12 -> 0.34254768
A17: Inventory Shrink | C17: =C12*Input!$P$43 -> 1125.35 | D17: =D12*Input!$P$43 -> 1390.6585 | E17: =E12*Input!$P$43 -> 1683.3705 | F17: =F12*Input!$P$43 -> 1538.9723 | G17: =G12*Input!$P$43 -> 1796.0311 | H17: =H12*Input!$P$43 -> 1642.6134 | I17: =I12*Input!$P$43 -> 1623.9739 | J17: =J12*Input!$P$43 -> 2516.5893 | ... N17: =N12*Input!$P$43 -> 1399.7668 | O17: =SUM(C17:N17) -> 19375 | P17: =O17/$O$12 -> 0.0125
A18: Freight on Goods Received | C18: =C11*Input!$P$42 -> 0 | D18: =D11*Input!$P$42 -> 0 | E18: =E11*Input!$P$42 -> 0 | F18: =F11*Input!$P$42 -> 0 | G18: =G11*Input!$P$42 -> 0 | H18: =H11*Input!$P$42 -> 0 | I18: =I11*Input!$P$42 -> 0 | J18: =J11*Input!$P$42 -> 0 | ... N18: =N11*Input!$P$42 -> 0 | O18: =SUM(C18:N18) -> 0 | P18: =O18/$O$12 -> 0
A19: New GPM% | C19: =VLOOKUP(MONTH(C6),Input!$R$53:$V$64,5) -> 0.6867683 | D19: =VLOOKUP(MONTH(D6),Input!$R$53:$V$64,5) -> 0.67216633 | E19: =VLOOKUP(MONTH(E6),Input!$R$53:$V$64,5) -> 0.72256255 | F19: =VLOOKUP(MONTH(F6),Input!$R$53:$V$64,5) -> 0.67919671 | G19: =VLOOKUP(MONTH(G6),Input!$R$53:$V$64,5) -> 0.72446135 | H19: =VLOOKUP(MONTH(H6),Input!$R$53:$V$64,5) -> 0.73768549 | I19: =VLOOKUP(MONTH(I6),Input!$R$53:$V$64,5) -> 0.92314635 | J19: =VLOOKUP(MONTH(J6),Input!$R$53:$V$64,5) -> 0.89541885 | ... N19: =VLOOKUP(MONTH(N6),Input!$R$53:$V$64,5) -> 0.90331766
A20: Cost of Goods Sold-New | C20: =C11*(1-C19) -> 281.99622 | D20: =D11*(1-D19) -> 364.72375 | E20: =E11*(1-E19) -> 373.62401 | F20: =F11*(1-F19) -> 394.96589 | G20: =G11*(1-G19) -> 395.90079 | H20: =H11*(1-H19) -> 344.70506 | I20: =I11*(1-I19) -> 99.846656 | J20: =J11*(1-J19) -> 210.55025 | ... N20: =N11*(1-N19) -> 108.26619 | O20: =SUM(C20:N20) -> 2826.2562 | P20: =O20/$O$12 -> 0.0018233911
A22: Total Cost of Sales | C22: =SUM(C16:C20) -> 35888.809 | D22: =SUM(D16:D20) -> 39784.506 | E22: =SUM(E16:E20) -> 46894.71 | F22: =SUM(F16:F20) -> 46262.831 | G22: =SUM(G16:G20) -> 48892.463 | H22: =SUM(H16:H20) -> 49093.47 | I22: =SUM(I16:I20) -> 43968.34 | J22: =SUM(J16:J20) -> 70682.928 | ... N22: =SUM(N16:N20) -> 39665.767 | O22: =SUM(C22:N22) -> 553159.9 | P22: =O22/$O$12 -> 0.35687735
A24: Gross Profit | C24: =C12-C22 -> 54139.188 | D24: =D12-D22 -> 71468.176 | E24: =E12-E22 -> 87774.929 | F24: =F12-F22 -> 76854.951 | G24: =G12-G22 -> 94790.025 | H24: =H12-H22 -> 82315.6 | I24: =I12-I22 -> 85949.57 | J24: =J12-J22 -> 130644.22 | ... N24: =N12-N22 -> 72315.579 | O24: =SUM(C24:N24) -> 996840.1 | P24: =O24/$O$12 -> 0.64312265
A25: % | C25: =C24/C12 -> 0.60135946 | D25: =D24/D12 -> 0.64239509 | E25: =E24/E12 -> 0.65177964 | F25: =F24/F12 -> 0.62423924 | G25: =G24/G12 -> 0.65971871 | H25: =H24/H12 -> 0.6264073 | I25: =I24/I12 -> 0.66156829 | J25: =J24/J12 -> 0.64891507 | ... O25: =O24/O12 -> 0.64312265
A28: EXPENSES
A29: Payroll Expenses
A30: =Input!C19 -> OWNER | C30: =Input!$C$21/12 -> 0 | D30: =Input!$C$21/12 -> 0 | E30: =Input!$C$21/12 -> 0 | F30: =Input!$C$21/12 -> 0 | G30: =Input!$C$21/12 -> 0 | H30: =Input!$C$21/12 -> 0 | I30: =Input!$C$21/12 -> 0 | J30: =Input!$C$21/12 -> 0 | ... N30: =Input!$C$21/12 -> 0 | O30: =SUM(C30:N30) -> 0 | P30: =O30/$O$12 -> 0
A31: =Input!C25 -> MANAGER | C31: =(Input!$C$27+Input!$E$27)/12+(Input!$G$27*Input!$C$14)/12 -> 5000 | D31: =(Input!$C$27+Input!$E$27)/12+(Input!$G$27*Input!$C$14)/12 -> 5000 | E31: =(Input!$C$27+Input!$E$27)/12+(Input!$G$27*Input!$C$14)/12 -> 5000 | F31: =(Input!$C$27+Input!$E$27)/12+(Input!$G$27*Input!$C$14)/12 -> 5000 | G31: =(Input!$C$27+Input!$E$27)/12+(Input!$G$27*Input!$C$14)/12 -> 5000 | H31: =(Input!$C$27+Input!$E$27)/12+(Input!$G$27*Input!$C$14)/12 -> 5000 | I31: =(Input!$C$27+Input!$E$27)/12+(Input!$G$27*Input!$C$14)/12 -> 5000 | J31: =(Input!$C$27+Input!$E$27)/12+(Input!$G$27*Input!$C$14)/12 -> 5000 | ... N31: =(Input!$C$27+Input!$E$27)/12+(Input!$G$27*Input!$C$14)/12 -> 5000 | O31: =SUM(C31:N31) -> 60000 | P31: =O31/$O$12 -> 0.038709677
A32: =Input!J6 -> HOURLY LABOR COST | C32: =Input!$M$6*C8 -> 0 | D32: =Input!$M$6*D8 -> 0 | E32: =Input!$M$6*E8 -> 0 | F32: =Input!$M$6*F8 -> 0 | G32: =Input!$M$6*G8 -> 0 | H32: =Input!$M$6*H8 -> 0 | I32: =Input!$M$6*I8 -> 0 | J32: =Input!$M$6*J8 -> 0 | ... N32: =Input!$M$6*N8 -> 0 | O32: =SUM(C32:N32) -> 0 | P32: =O32/$O$12 -> 0
A33: =Input!J7 -> PAYROLL TAXES | C33: =(C30+C31+C32)*Input!$M$7 -> 450 | D33: =(D30+D31+D32)*Input!$M$7 -> 450 | E33: =(E30+E31+E32)*Input!$M$7 -> 450 | F33: =(F30+F31+F32)*Input!$M$7 -> 450 | G33: =(G30+G31+G32)*Input!$M$7 -> 450 | H33: =(H30+H31+H32)*Input!$M$7 -> 450 | I33: =(I30+I31+I32)*Input!$M$7 -> 450 | J33: =(J30+J31+J32)*Input!$M$7 -> 450 | ... N33: =(N30+N31+N32)*Input!$M$7 -> 450 | O33: =SUM(C33:N33) -> 5400 | P33: =O33/$O$12 -> 0.003483871
A34: =Input!J9 -> WORKERS COMP INS | C34: =(C30+C31+C32)*Input!$M$9 -> 10 | D34: =(D30+D31+D32)*Input!$M$9 -> 10 | E34: =(E30+E31+E32)*Input!$M$9 -> 10 | F34: =(F30+F31+F32)*Input!$M$9 -> 10 | G34: =(G30+G31+G32)*Input!$M$9 -> 10 | H34: =(H30+H31+H32)*Input!$M$9 -> 10 | I34: =(I30+I31+I32)*Input!$M$9 -> 10 | J34: =(J30+J31+J32)*Input!$M$9 -> 10 | ... N34: =(N30+N31+N32)*Input!$M$9 -> 10 | O34: =SUM(C34:N34) -> 120 | P34: =O34/$O$12 -> 7.7419355e-05
A35: =Input!J8 -> PAYROLL SERVICES | C35: =Input!$M$8 -> 0 | D35: =Input!$M$8 -> 0 | E35: =Input!$M$8 -> 0 | F35: =Input!$M$8 -> 0 | G35: =Input!$M$8 -> 0 | H35: =Input!$M$8 -> 0 | I35: =Input!$M$8 -> 0 | J35: =Input!$M$8 -> 0 | ... N35: =Input!$M$8 -> 0 | O35: =SUM(C35:N35) -> 0 | P35: =O35/$O$12 -> 0
A36: subtotal Payroll | C36: =SUM(C30:C35) -> 5460 | D36: =SUM(D30:D35) -> 5460 | E36: =SUM(E30:E35) -> 5460 | F36: =SUM(F30:F35) -> 5460 | G36: =SUM(G30:G35) -> 5460 | H36: =SUM(H30:H35) -> 5460 | I36: =SUM(I30:I35) -> 5460 | J36: =SUM(J30:J35) -> 5460 | ... N36: =SUM(N30:N35) -> 5460 | O36: =SUM(C36:N36) -> 65520 | P36: =O36/$O$12 -> 0.042270968
A37: Operating Expenses
A38: =Input!J11 -> ADVERTISING | C38: =C12*Input!$M$11 -> 4951.5398 | D38: =D12*Input!$M$11 -> 6118.8975 | E38: =E12*Input!$M$11 -> 7406.8302 | F38: =F12*Input!$M$11 -> 6771.478 | G38: =G12*Input!$M$11 -> 7902.5368 | H38: =H12*Input!$M$11 -> 7227.4989 | I38: =I12*Input!$M$11 -> 7145.4851 | J38: =J12*Input!$M$11 -> 11072.993 | ... N38: =N12*Input!$M$11 -> 6158.974 | O38: =SUM(C38:N38) -> 85250 | P38: =O38/$O$12 -> 0.055
A39: =Input!J12 -> ACCOUNTING FEES | C39: =Input!$M$12 -> 0 | D39: =Input!$M$12 -> 0 | E39: =Input!$M$12 -> 0 | F39: =Input!$M$12 -> 0 | G39: =Input!$M$12 -> 0 | H39: =Input!$M$12 -> 0 | I39: =Input!$M$12 -> 0 | J39: =Input!$M$12 -> 0 | ... N39: =Input!$M$12 -> 0 | O39: =SUM(C39:N39) -> 0 | P39: =O39/$O$12 -> 0
A40: =Input!J13 -> ROYALTY | C40: =C12*Input!$M$13 -> 4501.3999 | D40: =D12*Input!$M$13 -> 5562.6341 | E40: =E12*Input!$M$13 -> 6733.482 | F40: =F12*Input!$M$13 -> 6155.8891 | G40: =G12*Input!$M$13 -> 7184.1244 | H40: =H12*Input!$M$13 -> 6570.4535 | I40: =I12*Input!$M$13 -> 6495.8955 | J40: =J12*Input!$M$13 -> 10066.357 | ... N40: =N12*Input!$M$13 -> 5599.0673 | O40: =SUM(C40:N40) -> 77500 | P40: =O40/$O$12 -> 0.05
A41: =Input!J14 -> BANK/CREDIT CARD CHARGES | C41: =C12*Input!$M$14 -> 0 | D41: =D12*Input!$M$14 -> 0 | E41: =E12*Input!$M$14 -> 0 | F41: =F12*Input!$M$14 -> 0 | G41: =G12*Input!$M$14 -> 0 | H41: =H12*Input!$M$14 -> 0 | I41: =I12*Input!$M$14 -> 0 | J41: =J12*Input!$M$14 -> 0 | ... N41: =N12*Input!$M$14 -> 0 | O41: =SUM(C41:N41) -> 0 | P41: =O41/$O$12 -> 0
A42: =Input!J15 -> CHECK GUARANTEE | C42: =C12*Input!$M$15 -> 0 | D42: =D12*Input!$M$15 -> 0 | E42: =E12*Input!$M$15 -> 0 | F42: =F12*Input!$M$15 -> 0 | G42: =G12*Input!$M$15 -> 0 | H42: =H12*Input!$M$15 -> 0 | I42: =I12*Input!$M$15 -> 0 | J42: =J12*Input!$M$15 -> 0 | ... N42: =N12*Input!$M$15 -> 0 | O42: =SUM(C42:N42) -> 0 | P42: =O42/$O$12 -> 0
A43: =Input!J17 -> RENT (Monthly: Base + CAM) | C43: =Input!$M$17 -> 15800 | D43: =Input!$M$17 -> 15800 | E43: =Input!$M$17 -> 15800 | F43: =Input!$M$17 -> 15800 | G43: =Input!$M$17 -> 15800 | H43: =Input!$M$17 -> 15800 | I43: =Input!$M$17 -> 15800 | J43: =Input!$M$17 -> 15800 | ... N43: =Input!$M$17 -> 15800 | O43: =SUM(C43:N43) -> 189600 | P43: =O43/$O$12 -> 0.12232258
A44: =Input!J18 -> SECURITY MONITORING | C44: =Input!$M$18 -> 60 | D44: =Input!$M$18 -> 60 | E44: =Input!$M$18 -> 60 | F44: =Input!$M$18 -> 60 | G44: =Input!$M$18 -> 60 | H44: =Input!$M$18 -> 60 | I44: =Input!$M$18 -> 60 | J44: =Input!$M$18 -> 60 | ... N44: =Input!$M$18 -> 60 | O44: =SUM(C44:N44) -> 720 | P44: =O44/$O$12 -> 0.00046451613
A45: =Input!J19 -> LEASING PAYMENT | C45: =Input!$M$19 -> 0 | D45: =Input!$M$19 -> 0 | E45: =Input!$M$19 -> 0 | F45: =Input!$M$19 -> 0 | G45: =Input!$M$19 -> 0 | H45: =Input!$M$19 -> 0 | I45: =Input!$M$19 -> 0 | J45: =Input!$M$19 -> 0 | ... N45: =Input!$M$19 -> 0 | O45: =SUM(C45:N45) -> 0 | P45: =O45/$O$12 -> 0
A46: =Input!J21 -> REPAIRS / MAINTANENCE | C46: =Input!$M$21 -> 269 | D46: =Input!$M$21 -> 269 | E46: =Input!$M$21 -> 269 | F46: =Input!$M$21 -> 269 | G46: =Input!$M$21 -> 269 | H46: =Input!$M$21 -> 269 | I46: =Input!$M$21 -> 269 | J46: =Input!$M$21 -> 269 | ... N46: =Input!$M$21 -> 269 | O46: =SUM(C46:N46) -> 3228 | P46: =O46/$O$12 -> 0.0020825806
A47: =Input!J22 -> BUS. TRAVEL/ENTERTAIN. | C47: =Input!$M$22 -> 309 | D47: =Input!$M$22 -> 309 | E47: =Input!$M$22 -> 309 | F47: =Input!$M$22 -> 309 | G47: =Input!$M$22 -> 309 | H47: =Input!$M$22 -> 309 | I47: =Input!$M$22 -> 309 | J47: =Input!$M$22 -> 309 | ... N47: =Input!$M$22 -> 309 | O47: =SUM(C47:N47) -> 3708 | P47: =O47/$O$12 -> 0.0023922581
A48: =Input!J23 -> BUSINESS VEHICLE | C48: =Input!$M$23 -> 476 | D48: =Input!$M$23 -> 476 | E48: =Input!$M$23 -> 476 | F48: =Input!$M$23 -> 476 | G48: =Input!$M$23 -> 476 | H48: =Input!$M$23 -> 476 | I48: =Input!$M$23 -> 476 | J48: =Input!$M$23 -> 476 | ... N48: =Input!$M$23 -> 476 | O48: =SUM(C48:N48) -> 5712 | P48: =O48/$O$12 -> 0.0036851613
A49: =Input!J25 -> OFFICE SUPPLIES & EXP | C49: =C12*Input!$M$25 -> 1800.5599 | D49: =D12*Input!$M$25 -> 2225.0536 | E49: =E12*Input!$M$25 -> 2693.3928 | F49: =F12*Input!$M$25 -> 2462.3556 | G49: =G12*Input!$M$25 -> 2873.6498 | H49: =H12*Input!$M$25 -> 2628.1814 | I49: =I12*Input!$M$25 -> 2598.3582 | J49: =J12*Input!$M$25 -> 4026.5429 | ... N49: =N12*Input!$M$25 -> 2239.6269 | O49: =SUM(C49:N49) -> 31000 | P49: =O49/$O$12 -> 0.02
...

Sheet Actuals
A2: INPUTS: | B2: ACTUALS | C2: ='P&LY1'!C6 -> 44561 | D2: ='P&LY1'!D6 -> 44592 | E2: ='P&LY1'!E6 -> 44620 | F2: ='P&LY1'!F6 -> 44651 | G2: ='P&LY1'!G6 -> 44681 | H2: ='P&LY1'!H6 -> 44712 | I2: ='P&LY1'!I6 -> 44742 | J2: ='P&LY1'!J6 -> 44773 | ... N2: ='P&LY1'!N6 -> 44895 | O2: Total
B3: Sales
B4: New Sales | O4: =SUM(C4:N4) -> 0
B5: Used Sales | O5: =SUM(C5:N5) -> 0
B6: Total Sales | C6: =SUM(C4:C5) -> 0 | D6: =SUM(D4:D5) -> 0 | E6: =SUM(E4:E5) -> 0 | F6: =SUM(F4:F5) -> 0 | G6: =SUM(G4:G5) -> 0 | H6: =SUM(H4:H5) -> 0 | I6: =SUM(I4:I5) -> 0 | J6: =SUM(J4:J5) -> 0 | ... O6: =SUM(O4:O5) -> 0
B7: COGS
B8: New COGS | O8: =SUM(C8:N8) -> 0
B9: Used COGS | O9: =SUM(C9:N9) -> 0
B11: Gross $ | C11: =C6-SUM(C8:C9) -> 0 | D11: =D6-SUM(D8:D9) -> 0 | E11: =E6-SUM(E8:E9) -> 0 | F11: =F6-SUM(F8:F9) -> 0 | G11: =G6-SUM(G8:G9) -> 0 | H11: =H6-SUM(H8:H9) -> 0 | I11: =I6-SUM(I8:I9) -> 0 | J11: =J6-SUM(J8:J9) -> 0 | ... O11: =O6-SUM(O8:O9) -> 0
B12: Gross % | C12: =C11/C6 -> #DIV/0! | D12: =D11/D6 -> #DIV/0! | E12: =E11/E6 -> #DIV/0! | F12: =F11/F6 -> #DIV/0! | G12: =G11/G6 -> #DIV/0! | H12: =H11/H6 -> #DIV/0! | I12: =I11/I6 -> #DIV/0! | J12: =J11/J6 -> #DIV/0! | ... O12: =O11/O6 -> #DIV/0!
B14: Subtotal Payroll
B16: Total Expenses
B18: Inventory Balance
B19: New Inv
B20: Used Inv
B22: Cash Balance
B24: (Automatically Calculated)
B25: Actual v. Budget Variance Analysis | C25: =C2 -> 44561 | D25: =D2 -> 44592 | E25: =E2 -> 44620 | F25: =F2 -> 44651 | G25: =G2 -> 44681 | H25: =H2 -> 44712 | I25: =I2 -> 44742 | J25: =J2 -> 44773 | ... N25: =N2 -> 44895
A26: New Sales | B26: Monthly Variance $ | C26: =IF(C4>0,C4-C69,"") | D26: =IF(D4>0,D4-D69,"") | E26: =IF(E4>0,E4-E69,"") | F26: =IF(F4>0,F4-F69,"") | G26: =IF(G4>0,G4-G69,"") | H26: =IF(H4>0,H4-H69,"") | I26: =IF(I4>0,I4-I69,"") | J26: =IF(J4>0,J4-J69,"") | ... O26: =IF(O4>0,O4-O69,"")
B27: Monthly Variance % | C27: =IF(C4>0,C26/C69,"") | D27: =IF(D4>0,D26/D69,"") | E27: =IF(E4>0,E26/E69,"") | F27: =IF(F4>0,F26/F69,"") | G27: =IF(G4>0,G26/G69,"") | H27: =IF(H4>0,H26/H69,"") | I27: =IF(I4>0,I26/I69,"") | J27: =IF(J4>0,J26/J69,"") | ... O27: =IF(O4>0,O26/O69,"")
B28: YTD $ | C28: =IF(C4>0,SUM($C4:C4)-SUM($C69:C69),"") | D28: =IF(D4>0,SUM($C4:D4)-SUM($C69:D69),"") | E28: =IF(E4>0,SUM($C4:E4)-SUM($C69:E69),"") | F28: =IF(F4>0,SUM($C4:F4)-SUM($C69:F69),"") | G28: =IF(G4>0,SUM($C4:G4)-SUM($C69:G69),"") | H28: =IF(H4>0,SUM($C4:H4)-SUM($C69:H69),"") | I28: =IF(I4>0,SUM($C4:I4)-SUM($C69:I69),"") | J28: =IF(J4>0,SUM($C4:J4)-SUM($C69:J69),"") | ... N28: =IF(N4>0,SUM($C4:N4)-SUM($C69:N69),"")
B29: YTD % | C29: =IF(C4>0,C28/SUM($C69:C69),"") | D29: =IF(D4>0,D28/SUM($C69:D69),"") | E29: =IF(E4>0,E28/SUM($C69:E69),"") | F29: =IF(F4>0,F28/SUM($C69:F69),"") | G29: =IF(G4>0,G28/SUM($C69:G69),"") | H29: =IF(H4>0,H28/SUM($C69:H69),"") | I29: =IF(I4>0,I28/SUM($C69:I69),"") | J29: =IF(J4>0,J28/SUM($C69:J69),"") | ... N29: =IF(N4>0,N28/SUM($C69:N69),"")
A31: Used Sales | B31: Monthly Variance $ | C31: =IF(C5>0,C5-C70,"") | D31: =IF(D5>0,D5-D70,"") | E31: =IF(E5>0,E5-E70,"") | F31: =IF(F5>0,F5-F70,"") | G31: =IF(G5>0,G5-G70,"") | H31: =IF(H5>0,H5-H70,"") | I31: =IF(I5>0,I5-I70,"") | J31: =IF(J5>0,J5-J70,"") | ... O31: =IF(O5>0,O5-O70,"")
B32: Monthly Variance % | C32: =IF(C5>0,C31/C70,"") | D32: =IF(D5>0,D31/D70,"") | E32: =IF(E5>0,E31/E70,"") | F32: =IF(F5>0,F31/F70,"") | G32: =IF(G5>0,G31/G70,"") | H32: =IF(H5>0,H31/H70,"") | I32: =IF(I5>0,I31/I70,"") | J32: =IF(J5>0,J31/J70,"") | ... O32: =IF(O5>0,O31/O70,"")
B33: YTD $ | C33: =IF(C5>0,SUM($C5:C5)-SUM($C70:C70),"") | D33: =IF(D5>0,SUM($C5:D5)-SUM($C70:D70),"") | E33: =IF(E5>0,SUM($C5:E5)-SUM($C70:E70),"") | F33: =IF(F5>0,SUM($C5:F5)-SUM($C70:F70),"") | G33: =IF(G5>0,SUM($C5:G5)-SUM($C70:G70),"") | H33: =IF(H5>0,SUM($C5:H5)-SUM($C70:H70),"") | I33: =IF(I5>0,SUM($C5:I5)-SUM($C70:I70),"") | J33: =IF(J5>0,SUM($C5:J5)-SUM($C70:J70),"") | ... N33: =IF(N5>0,SUM($C5:N5)-SUM($C70:N70),"")
B34: YTD % | C34: =IF(C5>0,C33/SUM($C70:C70),"") | D34: =IF(D5>0,D33/SUM($C70:D70),"") | E34: =IF(E5>0,E33/SUM($C70:E70),"") | F34: =IF(F5>0,F33/SUM($C70:F70),"") | G34: =IF(G5>0,G33/SUM($C70:G70),"") | H34: =IF(H5>0,H33/SUM($C70:H70),"") | I34: =IF(I5>0,I33/SUM($C70:I70),"") | J34: =IF(J5>0,J33/SUM($C70:J70),"") | ... N34: =IF(N5>0,N33/SUM($C70:N70),"")
A36: Total Sales
B37: Monthly Variance $ | C37: =IF(C6>0,C6-C71,"") | D37: =IF(D6>0,D6-D71,"") | E37: =IF(E6>0,E6-E71,"") | F37: =IF(F6>0,F6-F71,"") | G37: =IF(G6>0,G6-G71,"") | H37: =IF(H6>0,H6-H71,"") | I37: =IF(I6>0,I6-I71,"") | J37: =IF(J6>0,J6-J71,"") | ... O37: =IF(O6>0,O6-O71,"")
B38: Monthly Variance % | C38: =IF(C6>0,C37/C71,"") | D38: =IF(D6>0,D37/D71,"") | E38: =IF(E6>0,E37/E71,"") | F38: =IF(F6>0,F37/F71,"") | G38: =IF(G6>0,G37/G71,"") | H38: =IF(H6>0,H37/H71,"") | I38: =IF(I6>0,I37/I71,"") | J38: =IF(J6>0,J37/J71,"") | ... O38: =IF(O6>0,O37/O71,"")
B39: YTD $ | C39: =IF(C6>0,SUM($C6:C6)-SUM($C71:C71),"") | D39: =IF(D6>0,SUM($C6:D6)-SUM($C71:D71),"") | E39: =IF(E6>0,SUM($C6:E6)-SUM($C71:E71),"") | F39: =IF(F6>0,SUM($C6:F6)-SUM($C71:F71),"") | G39: =IF(G6>0,SUM($C6:G6)-SUM($C71:G71),"") | H39: =IF(H6>0,SUM($C6:H6)-SUM($C71:H71),"") | I39: =IF(I6>0,SUM($C6:I6)-SUM($C71:I71),"") | J39: =IF(J6>0,SUM($C6:J6)-SUM($C71:J71),"") | ... N39: =IF(N6>0,SUM($C6:N6)-SUM($C71:N71),"")
B40: YTD % | C40: =IF(C6>0,C39/SUM($C71:C71),"") | D40: =IF(D6>0,D39/SUM($C71:D71),"") | E40: =IF(E6>0,E39/SUM($C71:E71),"") | F40: =IF(F6>0,F39/SUM($C71:F71),"") | G40: =IF(G6>0,G39/SUM($C71:G71),"") | H40: =IF(H6>0,H39/SUM($C71:H71),"") | I40: =IF(I6>0,I39/SUM($C71:I71),"") | J40: =IF(J6>0,J39/SUM($C71:J71),"") | ... N40: =IF(N6>0,N39/SUM($C71:N71),"")
A42: Gross Profit | B42: Monthly Variance $ | C42: =IF(C11>0,C11-C76,"") | D42: =IF(D11>0,D11-D76,"") | E42: =IF(E11>0,E11-E76,"") | F42: =IF(F11>0,F11-F76,"") | G42: =IF(G11>0,G11-G76,"") | H42: =IF(H11>0,H11-H76,"") | I42: =IF(I11>0,I11-I76,"") | J42: =IF(J11>0,J11-J76,"") | ... O42: =IF(O11>0,O11-O76,"")
B43: Monthly Variance % | C43: =IF(C11>0,C42/C76,"") | D43: =IF(D11>0,D42/D76,"") | E43: =IF(E11>0,E42/E76,"") | F43: =IF(F11>0,F42/F76,"") | G43: =IF(G11>0,G42/G76,"") | H43: =IF(H11>0,H42/H76,"") | I43: =IF(I11>0,I42/I76,"") | J43: =IF(J11>0,J42/J76,"") | ... O43: =IF(O11>0,O42/O76,"")
B44: YTD $ | C44: =IF(C11>0,SUM($C11:C11)-SUM($C76:C76),"") | D44: =IF(D11>0,SUM($C11:D11)-SUM($C76:D76),"") | E44: =IF(E11>0,SUM($C11:E11)-SUM($C76:E76),"") | F44: =IF(F11>0,SUM($C11:F11)-SUM($C76:F76),"") | G44: =IF(G11>0,SUM($C11:G11)-SUM($C76:G76),"") | H44: =IF(H11>0,SUM($C11:H11)-SUM($C76:H76),"") | I44: =IF(I11>0,SUM($C11:I11)-SUM($C76:I76),"") | J44: =IF(J11>0,SUM($C11:J11)-SUM($C76:J76),"") | ... N44: =IF(N11>0,SUM($C11:N11)-SUM($C76:N76),"")
B45: YTD % | C45: =IF(C11>0,C44/SUM($C76:C76),"") | D45: =IF(D11>0,D44/SUM($C76:D76),"") | E45: =IF(E11>0,E44/SUM($C76:E76),"") | F45: =IF(F11>0,F44/SUM($C76:F76),"") | G45: =IF(G11>0,G44/SUM($C76:G76),"") | H45: =IF(H11>0,H44/SUM($C76:H76),"") | I45: =IF(I11>0,I44/SUM($C76:I76),"") | J45: =IF(J11>0,J44/SUM($C76:J76),"") | ... N45: =IF(N11>0,N44/SUM($C76:N76),"")
A47: Payroll | B47: Monthly Variance $ | C47: =IF(C14>0,C79-C14,"") | D47: =IF(D14>0,D79-D14,"") | E47: =IF(E14>0,E79-E14,"") | F47: =IF(F14>0,F79-F14,"") | G47: =IF(G14>0,G79-G14,"") | H47: =IF(H14>0,H79-H14,"") | I47: =IF(I14>0,I79-I14,"") | J47: =IF(J14>0,J79-J14,"") | ... N47: =IF(N14>0,N79-N14,"")
B48: Monthly Variance % | C48: =IF(C14>0,C47/C79,"") | D48: =IF(D14>0,D47/D79,"") | E48: =IF(E14>0,E47/E79,"") | F48: =IF(F14>0,F47/F79,"") | G48: =IF(G14>0,G47/G79,"") | H48: =IF(H14>0,H47/H79,"") | I48: =IF(I14>0,I47/I79,"") | J48: =IF(J14>0,J47/J79,"") | ... N48: =IF(N14>0,N47/N79,"")
B49: YTD $ | C49: =IF(C14>0,SUM($C79:C79)-SUM($C14:C14),"") | D49: =IF(D14>0,SUM($C79:D79)-SUM($C14:D14),"") | E49: =IF(E14>0,SUM($C79:E79)-SUM($C14:E14),"") | F49: =IF(F14>0,SUM($C79:F79)-SUM($C14:F14),"") | G49: =IF(G14>0,SUM($C79:G79)-SUM($C14:G14),"") | H49: =IF(H14>0,SUM($C79:H79)-SUM($C14:H14),"") | I49: =IF(I14>0,SUM($C79:I79)-SUM($C14:I14),"") | J49: =IF(J14>0,SUM($C79:J79)-SUM($C14:J14),"") | ... N49: =IF(N14>0,SUM($C79:N79)-SUM($C14:N14),"")
B50: YTD % | C50: =IF(C14>0,C49/SUM($C79:C79),"") | D50: =IF(D14>0,D49/SUM($C79:D79),"") | E50: =IF(E14>0,E49/SUM($C79:E79),"") | F50: =IF(F14>0,F49/SUM($C79:F79),"") | G50: =IF(G14>0,G49/SUM($C79:G79),"") | H50: =IF(H14>0,H49/SUM($C79:H79),"") | I50: =IF(I14>0,I49/SUM($C79:I79),"") | J50: =IF(J14>0,J49/SUM($C79:J79),"") | ... N50: =IF(N14>0,N49/SUM($C79:N79),"")
A52: Total Expenses | B52: Monthly Variance $ | C52: =IF(C16>0,C81-C16,"") | D52: =IF(D16>0,D81-D16,"") | E52: =IF(E16>0,E81-E16,"") | F52: =IF(F16>0,F81-F16,"") | G52: =IF(G16>0,G81-G16,"") | H52: =IF(H16>0,H81-H16,"") | I52: =IF(I16>0,I81-I16,"") | J52: =IF(J16>0,J81-J16,"") | ... N52: =IF(N16>0,N81-N16,"")
...

Sheet P&LY2
A2: =Input!C6 -> Bob, Lori & Adam Brown
A3: =Input!C9+366 -> 44927
A4: =Input!C7 -> Ann Arbor
A6: MONTH | C6: =DATE(YEAR('P&LY1'!N6),MONTH('P&LY1'!N6)+1,DAY('P&LY1'!N6)) -> 44926 | D6: =DATE(YEAR(C6),MONTH(C6)+1,DAY(C6)) -> 44957 | E6: =DATE(YEAR(D6),MONTH(D6)+1,DAY(D6)) -> 44985 | F6: =DATE(YEAR(E6),MONTH(E6)+1,DAY(E6)) -> 45016 | G6: =DATE(YEAR(F6),MONTH(F6)+1,DAY(F6)) -> 45046 | H6: =DATE(YEAR(G6),MONTH(G6)+1,DAY(G6)) -> 45077 | I6: =DATE(YEAR(H6),MONTH(H6)+1,DAY(H6)) -> 45107 | J6: =DATE(YEAR(I6),MONTH(I6)+1,DAY(I6)) -> 45138 | K6: =DATE(YEAR(J6),MONTH(J6)+1,DAY(J6)) -> 45169 | ... N6: =DATE(YEAR(M6),MONTH(M6)+1,DAY(M6)) -> 45260 | O6: Total | P6: Percent of Sales
A8: Sales Index | C8: ='P&LY1'!C8 -> 0.058082579 | D8: ='P&LY1'!D8 -> 0.071775924 | E8: ='P&LY1'!E8 -> 0.086883638 | F8: ='P&LY1'!F8 -> 0.079430827 | G8: ='P&LY1'!G8 -> 0.092698379 | H8: ='P&LY1'!H8 -> 0.084780045 | I8: ='P&LY1'!I8 -> 0.083818007 | J8: ='P&LY1'!J8 -> 0.12988848 | ... N8: ='P&LY1'!N8 -> 0.072246029 | O8: =SUM(C8:N8) -> 1
A10: SALES-Used | C10: =C8*Input!$G$15 -> 94475.38 | D10: =D8*Input!$G$15 -> 116748.56 | E10: =E8*Input!$G$15 -> 141322.32 | F10: =F8*Input!$G$15 -> 129199.8 | G10: =G8*Input!$G$15 -> 150780.4 | H10: =H8*Input!$G$15 -> 137900.68 | I10: =I8*Input!$G$15 -> 136335.85 | J10: =J8*Input!$G$15 -> 211272.71 | ... N10: =N8*Input!$G$15 -> 117513.22 | O10: =SUM(C10:N10) -> 1626570
A11: SALES-New | C11: =C8*Input!$I$15 -> 954.29677 | D11: =D8*Input!$I$15 -> 1179.2784 | E11: =E8*Input!$I$15 -> 1427.4982 | F11: =F8*Input!$I$15 -> 1305.0485 | G11: =G8*Input!$I$15 -> 1523.0344 | H11: =H8*Input!$I$15 -> 1392.9361 | I11: =I8*Input!$I$15 -> 1377.1298 | J11: =J8*Input!$I$15 -> 2134.0677 | ... N11: =N8*Input!$I$15 -> 1187.0023 | O11: =SUM(C11:N11) -> 16430
A12: Total Sales | C12: =SUM(C10:C11) -> 95429.677 | D12: =SUM(D10:D11) -> 117927.84 | E12: =SUM(E10:E11) -> 142749.82 | F12: =SUM(F10:F11) -> 130504.85 | G12: =SUM(G10:G11) -> 152303.44 | H12: =SUM(H10:H11) -> 139293.61 | I12: =SUM(I10:I11) -> 137712.98 | J12: =SUM(J10:J11) -> 213406.77 | ... N12: =SUM(N10:N11) -> 118700.23 | O12: =SUM(C12:N12) -> 1643000 | P12: =O12/$O$12 -> 1
A14: COST OF SALES
A15: Used GPM% | C15: =VLOOKUP(MONTH(C6),Input!$R$67:$V$78,3) -> 0.62313072 | D15: =VLOOKUP(MONTH(D6),Input!$R$67:$V$78,3) -> 0.66472673 | E15: =VLOOKUP(MONTH(E6),Input!$R$67:$V$78,3) -> 0.67369634 | F15: =VLOOKUP(MONTH(F6),Input!$R$67:$V$78,3) -> 0.64631595 | G15: =VLOOKUP(MONTH(G6),Input!$R$67:$V$78,3) -> 0.68169609 | H15: =VLOOKUP(MONTH(H6),Input!$R$67:$V$78,3) -> 0.64791521 | I15: =VLOOKUP(MONTH(I6),Input!$R$67:$V$78,3) -> 0.68155953 | J15: =VLOOKUP(MONTH(J6),Input!$R$67:$V$78,3) -> 0.66905588 | ... N15: =VLOOKUP(MONTH(N6),Input!$R$67:$V$78,3) -> 0.66581541
A16: Cost of Goods Sold-Used | C16: =C10*(1-C15) -> 35604.869 | D16: =D10*(1-D15) -> 39142.673 | E16: =E10*(1-E15) -> 46113.99 | F16: =F10*(1-F15) -> 45695.908 | G16: =G10*(1-G15) -> 47993.991 | H16: =H10*(1-H15) -> 48552.732 | I16: =I10*(1-I15) -> 43414.854 | J16: =J10*(1-J15) -> 69919.459 | ... N16: =N10*(1-N15) -> 39271.108 | O16: =SUM(C16:N16) -> 546540.13 | P16: =O16/$O$12 -> 0.33264768 | S16: =AVERAGE($C$16:$N$16) -> 45545.011 | T16: =AVERAGE($C$16:$N$16) -> 45545.011 | U16: =AVERAGE($C$16:$N$16) -> 45545.011 | V16: =AVERAGE($C$16:$N$16) -> 45545.011 | W16: =AVERAGE($C$16:$N$16) -> 45545.011 | X16: =AVERAGE($C$16:$N$16) -> 45545.011 | Y16: =AVERAGE($C$16:$N$16) -> 45545.011
A17: Inventory Shrink | C17: =C12*Input!$P$57 -> 1192.871 | D17: =D12*Input!$P$57 -> 1474.098 | E17: =E12*Input!$P$57 -> 1784.3727 | F17: =F12*Input!$P$57 -> 1631.3106 | G17: =G12*Input!$P$57 -> 1903.793 | H17: =H12*Input!$P$57 -> 1741.1702 | I17: =I12*Input!$P$57 -> 1721.4123 | J17: =J12*Input!$P$57 -> 2667.5847 | ... N17: =N12*Input!$P$57 -> 1483.7528 | O17: =SUM(C17:N17) -> 20537.5 | P17: =O17/$O$12 -> 0.0125
A18: Freight on Goods Received | C18: =C11*Input!$P$56 -> 0 | D18: =D11*Input!$P$56 -> 0 | E18: =E11*Input!$P$56 -> 0 | F18: =F11*Input!$P$56 -> 0 | G18: =G11*Input!$P$56 -> 0 | H18: =H11*Input!$P$56 -> 0 | I18: =I11*Input!$P$56 -> 0 | J18: =J11*Input!$P$56 -> 0 | ... N18: =N11*Input!$P$56 -> 0 | O18: =SUM(C18:N18) -> 0 | P18: =O18/$O$12 -> 0
A19: New GPM% | C19: =VLOOKUP(MONTH(C6),Input!$R$67:$V$78,5) -> 0.6967683 | D19: =VLOOKUP(MONTH(D6),Input!$R$67:$V$78,5) -> 0.68216633 | E19: =VLOOKUP(MONTH(E6),Input!$R$67:$V$78,5) -> 0.73256255 | F19: =VLOOKUP(MONTH(F6),Input!$R$67:$V$78,5) -> 0.68919671 | G19: =VLOOKUP(MONTH(G6),Input!$R$67:$V$78,5) -> 0.73446135 | H19: =VLOOKUP(MONTH(H6),Input!$R$67:$V$78,5) -> 0.74768549 | I19: =VLOOKUP(MONTH(I6),Input!$R$67:$V$78,5) -> 0.93314635 | J19: =VLOOKUP(MONTH(J6),Input!$R$67:$V$78,5) -> 0.90541885 | ... N19: =VLOOKUP(MONTH(N6),Input!$R$67:$V$78,5) -> 0.91331766
A20: Cost of Goods Sold-New | C20: =C11*(1-Input!$V67) -> 289.37303 | D20: =D11*(1-Input!$V68) -> 374.81439 | E20: =E11*(1-Input!$V69) -> 381.76647 | F20: =F11*(1-Input!$V70) -> 405.61336 | G20: =G11*(1-Input!$V71) -> 404.42449 | H20: =H11*(1-Input!$V72) -> 351.458 | I20: =I11*(1-Input!$V73) -> 92.066156 | J20: =J11*(1-Input!$V74) -> 201.84259 | K20: =K11*(1-Input!$V75) -> 20.576562 | L20: =L11*(1-Input!$V76) -> 98.239715 | M20: =M11*(1-Input!$V77) -> 108.46464 | N20: =N11*(1-Input!$V78) -> 102.89214 | O20: =SUM(C20:N20) -> 2831.5315 | P20: =O20/$O$12 -> 0.0017233911 | S20: =AVERAGE($C20:$N20) -> 235.96096 | T20: =AVERAGE($C20:$N20) -> 235.96096 | U20: =AVERAGE($C20:$N20) -> 235.96096 | V20: =AVERAGE($C20:$N20) -> 235.96096 | W20: =AVERAGE($C20:$N20) -> 235.96096 | X20: =AVERAGE($C20:$N20) -> 235.96096 | Y20: =AVERAGE($C20:$N20) -> 235.96096 | Z20: =AVERAGE($C20:$N20) -> 235.96096 | ... AF20: =AVERAGE($C20:$N20) -> 235.96096
A22: Total Cost of Sales | C22: =SUM(C16:C20) -> 37087.81 | D22: =SUM(D16:D20) -> 40992.267 | E22: =SUM(E16:E20) -> 48280.861 | F22: =SUM(F16:F20) -> 47733.521 | G22: =SUM(G16:G20) -> 50302.943 | H22: =SUM(H16:H20) -> 50646.108 | I22: =SUM(I16:I20) -> 45229.265 | J22: =SUM(J16:J20) -> 72789.792 | ... N22: =SUM(N16:N20) -> 40858.666 | O22: =SUM(C22:N22) -> 569919.03 | P22: =O22/$O$12 -> 0.34687707
A24: Gross Profit | C24: =C12-C22 -> 58341.867 | D24: =D12-D22 -> 76935.576 | E24: =E12-E22 -> 94468.956 | F24: =F12-F22 -> 82771.327 | G24: =G12-G22 -> 102000.49 | H24: =H12-H22 -> 88647.507 | I24: =I12-I22 -> 92483.72 | J24: =J12-J22 -> 140616.98 | ... N24: =N12-N22 -> 77841.56 | O24: =SUM(C24:N24) -> 1073081 | P24: =O24/$O$12 -> 0.65312293
A25: % | C25: =C24/C12 -> 0.61135979 | D25: =D24/D12 -> 0.65239534 | E25: =E24/E12 -> 0.66177987 | F25: =F24/F12 -> 0.63423948 | G25: =G24/G12 -> 0.66971892 | H25: =H24/H12 -> 0.63640754 | I25: =I24/I12 -> 0.67156862 | J25: =J24/J12 -> 0.65891527 | ... O25: =O24/O12 -> 0.65312293
A28: EXPENSES
A29: Payroll Expenses
A30: =Input!C19 -> OWNER | C30: =Input!$C$22/12 -> 0 | D30: =Input!$C$22/12 -> 0 | E30: =Input!$C$22/12 -> 0 | F30: =Input!$C$22/12 -> 0 | G30: =Input!$C$22/12 -> 0 | H30: =Input!$C$22/12 -> 0 | I30: =Input!$C$22/12 -> 0 | J30: =Input!$C$22/12 -> 0 | ... N30: =Input!$C$22/12 -> 0 | O30: =SUM(C30:N30) -> 0 | P30: =O30/$O$12 -> 0
A31: =Input!C25 -> MANAGER | C31: =(Input!$C$28+Input!$E$28)/12+(Input!$G$28*Input!$C$15)/12 -> 5000 | D31: =(Input!$C$28+Input!$E$28)/12+(Input!$G$28*Input!$C$15)/12 -> 5000 | E31: =(Input!$C$28+Input!$E$28)/12+(Input!$G$28*Input!$C$15)/12 -> 5000 | F31: =(Input!$C$28+Input!$E$28)/12+(Input!$G$28*Input!$C$15)/12 -> 5000 | G31: =(Input!$C$28+Input!$E$28)/12+(Input!$G$28*Input!$C$15)/12 -> 5000 | H31: =(Input!$C$28+Input!$E$28)/12+(Input!$G$28*Input!$C$15)/12 -> 5000 | I31: =(Input!$C$28+Input!$E$28)/12+(Input!$G$28*Input!$C$15)/12 -> 5000 | J31: =(Input!$C$28+Input!$E$28)/12+(Input!$G$28*Input!$C$15)/12 -> 5000 | ... N31: =(Input!$C$28+Input!$E$28)/12+(Input!$G$28*Input!$C$15)/12 -> 5000 | O31: =SUM(C31:N31) -> 60000 | P31: =O31/$O$12 -> 0.036518564
A32: =Input!J6 -> HOURLY LABOR COST | C32: =Input!$N$6*C8 -> 0 | D32: =Input!$N$6*D8 -> 0 | E32: =Input!$N$6*E8 -> 0 | F32: =Input!$N$6*F8 -> 0 | G32: =Input!$N$6*G8 -> 0 | H32: =Input!$N$6*H8 -> 0 | I32: =Input!$N$6*I8 -> 0 | J32: =Input!$N$6*J8 -> 0 | ... N32: =Input!$N$6*N8 -> 0 | O32: =SUM(C32:N32) -> 0 | P32: =O32/$O$12 -> 0
A33: =Input!J7 -> PAYROLL TAXES | C33: =(C30+C31+C32)*Input!$M$7 -> 450 | D33: =(D30+D31+D32)*Input!$M$7 -> 450 | E33: =(E30+E31+E32)*Input!$M$7 -> 450 | F33: =(F30+F31+F32)*Input!$M$7 -> 450 | G33: =(G30+G31+G32)*Input!$M$7 -> 450 | H33: =(H30+H31+H32)*Input!$M$7 -> 450 | I33: =(I30+I31+I32)*Input!$M$7 -> 450 | J33: =(J30+J31+J32)*Input!$M$7 -> 450 | ... N33: =(N30+N31+N32)*Input!$M$7 -> 450 | O33: =SUM(C33:N33) -> 5400 | P33: =O33/$O$12 -> 0.0032866707
A34: =Input!J9 -> WORKERS COMP INS | C34: =(C30+C31+C32)*Input!$M$9 -> 10 | D34: =(D30+D31+D32)*Input!$M$9 -> 10 | E34: =(E30+E31+E32)*Input!$M$9 -> 10 | F34: =(F30+F31+F32)*Input!$M$9 -> 10 | G34: =(G30+G31+G32)*Input!$M$9 -> 10 | H34: =(H30+H31+H32)*Input!$M$9 -> 10 | I34: =(I30+I31+I32)*Input!$M$9 -> 10 | J34: =(J30+J31+J32)*Input!$M$9 -> 10 | ... N34: =(N30+N31+N32)*Input!$M$9 -> 10 | O34: =SUM(C34:N34) -> 120 | P34: =O34/$O$12 -> 7.3037127e-05
A35: =Input!J8 -> PAYROLL SERVICES | C35: =Input!$M$8 -> 0 | D35: =Input!$M$8 -> 0 | E35: =Input!$M$8 -> 0 | F35: =Input!$M$8 -> 0 | G35: =Input!$M$8 -> 0 | H35: =Input!$M$8 -> 0 | I35: =Input!$M$8 -> 0 | J35: =Input!$M$8 -> 0 | ... N35: =Input!$M$8 -> 0 | O35: =SUM(C35:N35) -> 0 | P35: =O35/$O$12 -> 0
A36: Operating Expenses
A37: =Input!J11 -> ADVERTISING | C37: =C12*Input!$M$11 -> 5248.6322 | D37: =D12*Input!$M$11 -> 6486.0314 | E37: =E12*Input!$M$11 -> 7851.24 | F37: =F12*Input!$M$11 -> 7177.7666 | G37: =G12*Input!$M$11 -> 8376.689 | H37: =H12*Input!$M$11 -> 7661.1488 | I37: =I12*Input!$M$11 -> 7574.2142 | J37: =J12*Input!$M$11 -> 11737.373 | ... N37: =N12*Input!$M$11 -> 6528.5124 | O37: =SUM(C37:N37) -> 90365 | P37: =O37/$O$12 -> 0.055
A38: =Input!J12 -> ACCOUNTING FEES | C38: =Input!$M$12 -> 0 | D38: =Input!$M$12 -> 0 | E38: =Input!$M$12 -> 0 | F38: =Input!$M$12 -> 0 | G38: =Input!$M$12 -> 0 | H38: =Input!$M$12 -> 0 | I38: =Input!$M$12 -> 0 | J38: =Input!$M$12 -> 0 | ... N38: =Input!$M$12 -> 0 | O38: =SUM(C38:N38) -> 0 | P38: =O38/$O$12 -> 0
A39: =Input!J13 -> ROYALTY | C39: =C12*Input!$M$13 -> 4771.4838 | D39: =D12*Input!$M$13 -> 5896.3921 | E39: =E12*Input!$M$13 -> 7137.4909 | F39: =F12*Input!$M$13 -> 6525.2424 | G39: =G12*Input!$M$13 -> 7615.1719 | H39: =H12*Input!$M$13 -> 6964.6807 | I39: =I12*Input!$M$13 -> 6885.6492 | J39: =J12*Input!$M$13 -> 10670.339 | ... N39: =N12*Input!$M$13 -> 5935.0113 | O39: =SUM(C39:N39) -> 82150 | P39: =O39/$O$12 -> 0.05
A40: =Input!J14 -> BANK/CREDIT CARD CHARGES | C40: =C12*Input!$M$14 -> 0 | D40: =D12*Input!$M$14 -> 0 | E40: =E12*Input!$M$14 -> 0 | F40: =F12*Input!$M$14 -> 0 | G40: =G12*Input!$M$14 -> 0 | H40: =H12*Input!$M$14 -> 0 | I40: =I12*Input!$M$14 -> 0 | J40: =J12*Input!$M$14 -> 0 | ... N40: =N12*Input!$M$14 -> 0 | O40: =SUM(C40:N40) -> 0 | P40: =O40/$O$12 -> 0
A41: =Input!J15 -> CHECK GUARANTEE | C41: =C12*Input!$M$15 -> 0 | D41: =D12*Input!$M$15 -> 0 | E41: =E12*Input!$M$15 -> 0 | F41: =F12*Input!$M$15 -> 0 | G41: =G12*Input!$M$15 -> 0 | H41: =H12*Input!$M$15 -> 0 | I41: =I12*Input!$M$15 -> 0 | J41: =J12*Input!$M$15 -> 0 | ... N41: =N12*Input!$M$15 -> 0 | O41: =SUM(C41:N41) -> 0 | P41: =O41/$O$12 -> 0
A42: =Input!J17 -> RENT (Monthly: Base + CAM) | C42: =Input!$M$17 -> 15800 | D42: =Input!$M$17 -> 15800 | E42: =Input!$M$17 -> 15800 | F42: =Input!$M$17 -> 15800 | G42: =Input!$M$17 -> 15800 | H42: =Input!$M$17 -> 15800 | I42: =Input!$M$17 -> 15800 | J42: =Input!$M$17 -> 15800 | ... N42: =Input!$M$17 -> 15800 | O42: =SUM(C42:N42) -> 189600 | P42: =O42/$O$12 -> 0.11539866
A43: =Input!J18 -> SECURITY MONITORING | C43: =Input!$M$18 -> 60 | D43: =Input!$M$18 -> 60 | E43: =Input!$M$18 -> 60 | F43: =Input!$M$18 -> 60 | G43: =Input!$M$18 -> 60 | H43: =Input!$M$18 -> 60 | I43: =Input!$M$18 -> 60 | J43: =Input!$M$18 -> 60 | ... N43: =Input!$M$18 -> 60 | O43: =SUM(C43:N43) -> 720 | P43: =O43/$O$12 -> 0.00043822276
A44: =Input!J19 -> LEASING PAYMENT | C44: =Input!$M$19 -> 0 | D44: =Input!$M$19 -> 0 | E44: =Input!$M$19 -> 0 | F44: =Input!$M$19 -> 0 | G44: =Input!$M$19 -> 0 | H44: =Input!$M$19 -> 0 | I44: =Input!$M$19 -> 0 | J44: =Input!$M$19 -> 0 | ... N44: =Input!$M$19 -> 0 | O44: =SUM(C44:N44) -> 0 | P44: =O44/$O$12 -> 0
A45: =Input!J21 -> REPAIRS / MAINTANENCE | C45: =Input!$M$21 -> 269 | D45: =Input!$M$21 -> 269 | E45: =Input!$M$21 -> 269 | F45: =Input!$M$21 -> 269 | G45: =Input!$M$21 -> 269 | H45: =Input!$M$21 -> 269 | I45: =Input!$M$21 -> 269 | J45: =Input!$M$21 -> 269 | ... N45: =Input!$M$21 -> 269 | O45: =SUM(C45:N45) -> 3228 | P45: =O45/$O$12 -> 0.0019646987
A46: =Input!J22 -> BUS. TRAVEL/ENTERTAIN. | C46: =Input!$M$22 -> 309 | D46: =Input!$M$22 -> 309 | E46: =Input!$M$22 -> 309 | F46: =Input!$M$22 -> 309 | G46: =Input!$M$22 -> 309 | H46: =Input!$M$22 -> 309 | I46: =Input!$M$22 -> 309 | J46: =Input!$M$22 -> 309 | ... N46: =Input!$M$22 -> 309 | O46: =SUM(C46:N46) -> 3708 | P46: =O46/$O$12 -> 0.0022568472
A47: =Input!J23 -> BUSINESS VEHICLE | C47: =Input!$M$23 -> 476 | D47: =Input!$M$23 -> 476 | E47: =Input!$M$23 -> 476 | F47: =Input!$M$23 -> 476 | G47: =Input!$M$23 -> 476 | H47: =Input!$M$23 -> 476 | I47: =Input!$M$23 -> 476 | J47: =Input!$M$23 -> 476 | ... N47: =Input!$M$23 -> 476 | O47: =SUM(C47:N47) -> 5712 | P47: =O47/$O$12 -> 0.0034765673
A48: =Input!J25 -> OFFICE SUPPLIES & EXP | C48: =C12*Input!$M$25 -> 1908.5935 | D48: =D12*Input!$M$25 -> 2358.5569 | E48: =E12*Input!$M$25 -> 2854.9964 | F48: =F12*Input!$M$25 -> 2610.097 | G48: =G12*Input!$M$25 -> 3046.0687 | H48: =H12*Input!$M$25 -> 2785.8723 | I48: =I12*Input!$M$25 -> 2754.2597 | J48: =J12*Input!$M$25 -> 4268.1355 | ... N48: =N12*Input!$M$25 -> 2374.0045 | O48: =SUM(C48:N48) -> 32860 | P48: =O48/$O$12 -> 0.02
A49: =Input!J26 -> CELL PHONE | C49: =Input!$M$26 -> 108 | D49: =Input!$M$26 -> 108 | E49: =Input!$M$26 -> 108 | F49: =Input!$M$26 -> 108 | G49: =Input!$M$26 -> 108 | H49: =Input!$M$26 -> 108 | I49: =Input!$M$26 -> 108 | J49: =Input!$M$26 -> 108 | ... N49: =Input!$M$26 -> 108 | O49: =SUM(C49:N49) -> 1296 | P49: =O49/$O$12 -> 0.00078880097
...

Sheet Breakeven Calculation
A1: Breakeven Analysis (based upon Year 1 P&L) | F1: Breakeven Amounts
F3: Daily | H3: =H6/7 -> 1625.1348
F6: Weekly | H6: =H12/52 -> 11375.943
A7: Variable Expenses | B7: % | C7: Monthly Ave | D7: Annual
A8: COGS - USED | B8: ='P&LY1'!P16 -> 0.34254768 | C8: =D8/12 -> 44245.741 | D8: ='P&LY1'!O16 -> 530948.9
A9: COGS - NEW | B9: ='P&LY1'!P20 -> 0.0018233911 | C9: =D9/12 -> 235.52135 | D9: ='P&LY1'!O20 -> 2826.2562 | F9: Monthly | H9: =H12/12 -> 49295.754
A10: ='P&LY1'!A38 -> ADVERTISING | B10: ='P&LY1'!P38 -> 0.055 | C10: =D10/12 -> 7104.1667 | D10: ='P&LY1'!O38 -> 85250
A11: ='P&LY1'!A40 -> ROYALTY | B11: ='P&LY1'!P40 -> 0.05 | C11: =D11/12 -> 6458.3333 | D11: ='P&LY1'!O40 -> 77500
A12: ='P&LY1'!A32 -> HOURLY LABOR COST | B12: ='P&LY1'!P32 -> 0 | C12: =D12/12 -> 0 | D12: ='P&LY1'!O32 -> 0 | F12: Yearly | H12: =D45/H19 -> 591549.05
A13: FREIGHT FOR INBOUND INVENTORY | B13: ='P&LY1'!P18 -> 0 | C13: =D13/12 -> 0 | D13: ='P&LY1'!O18 -> 0
A14: ='P&LY1'!A41 -> BANK/CREDIT CARD CHARGES | B14: =SUM('P&LY1'!P41:P42) -> 0 | C14: =D14/12 -> 0 | D14: =SUM('P&LY1'!O41:O42) -> 0
A15: SHRINK | B15: ='P&LY1'!P17 -> 0.0125 | C15: =D15/12 -> 1614.5833 | D15: ='P&LY1'!O17 -> 19375
A16: PAYROLL TAXES | B16: ='P&LY1'!P33 -> 0.003483871 | C16: =D16/12 -> 450 | D16: ='P&LY1'!O33 -> 5400
A17: WORKERS COMP INS | B17: ='P&LY1'!P34 -> 7.7419355e-05 | C17: =D17/12 -> 10 | D17: ='P&LY1'!O34 -> 120
A18: OFFICE SUPPLIES & EXP | B18: ='P&LY1'!P49 -> 0.02 | C18: =D18/12 -> 2583.3333 | D18: ='P&LY1'!O49 -> 31000 | F18: "For every dollar in sales, I have this many cents to cover fixed expenses."
B19: =SUM(B8:B18) -> 0.48543236 | C19: =SUM(C8:C18) -> 62701.679 | D19: =SUM(D8:D18) -> 752420.15 | F19: Contribution Margin | H19: =100%-B19 -> 0.51456764
A21: Fixed Expenses | B21: % | C21: Monthly Ave | D21: Annual
A22: OWNER SALARY | B22: =D22/$H$12 -> 0 | C22: =D22/12 -> 0 | D22: ='P&LY1'!O30 -> 0
A23: MANAGER SALARY | B23: =D23/$H$12 -> 0.10142861 | C23: =D23/12 -> 5000 | D23: ='P&LY1'!O31 -> 60000
A24: PAYROLL SERVICES | B24: =D24/$H$12 -> 0 | C24: =D24/12 -> 0 | D24: ='P&LY1'!O35 -> 0 | F24: Increase in Fixed Expenses
A25: ACCOUNTING FEES | B25: =D25/$H$12 -> 0 | C25: =D25/12 -> 0 | D25: ='P&LY1'!O39 -> 0
A26: RENT (Base + CAM) | B26: =D26/$H$12 -> 0.32051442 | C26: =D26/12 -> 15800 | D26: ='P&LY1'!O43 -> 189600
A27: SECURITY MONITORING | B27: =D27/$H$12 -> 0.0012171434 | C27: =D27/12 -> 60 | D27: ='P&LY1'!O44 -> 720 | F27: Increase in Sales to cover additional Fixed Expenses | H27: =H24/H19 -> 0
A28: LEASING PAYMENT | B28: =D28/$H$12 -> 0 | C28: =D28/12 -> 0 | D28: ='P&LY1'!O45 -> 0
A29: REPAIRS / MAINTANENCE | B29: =D29/$H$12 -> 0.0054568594 | C29: =D29/12 -> 269 | D29: ='P&LY1'!O46 -> 3228
A30: BUS. TRAVEL/ENTERTAIN. | B30: =D30/$H$12 -> 0.0062682883 | C30: =D30/12 -> 309 | D30: ='P&LY1'!O47 -> 3708
A31: BUSINESS VEHICLE | B31: =D31/$H$12 -> 0.009656004 | C31: =D31/12 -> 476 | D31: ='P&LY1'!O48 -> 5712
A32: CELL PHONE | B32: =D32/$H$12 -> 0.0021908581 | C32: =D32/12 -> 108 | D32: ='P&LY1'!O50 -> 1296
A33: TELEPHONE/INTERNET | B33: =D33/$H$12 -> 0.00687686 | C33: =D33/12 -> 339 | D33: ='P&LY1'!O51 -> 4068
A34: UTILITIES | B34: =D34/$H$12 -> 0.016472007 | C34: =D34/12 -> 812 | D34: ='P&LY1'!O52 -> 9744
A35: INSURANCE-BUSINESS | B35: =D35/$H$12 -> 0.015031721 | C35: =D35/12 -> 741 | D35: ='P&LY1'!O53 -> 8892
A36: EMPLOYEE HEALTH INSURANCE/BENEFITS | B36: =D36/$H$12 -> 0.010690576 | C36: =D36/12 -> 527 | D36: ='P&LY1'!O54 -> 6324
A37: OUTSIDE SERVICES | B37: =D37/$H$12 -> 0 | C37: =D37/12 -> 0 | D37: ='P&LY1'!O55 -> 0
A38: STORE OPERATING EXPENSE | B38: =D38/$H$12 -> 0.018764294 | C38: =D38/12 -> 925 | D38: ='P&LY1'!O56 -> 11100
A39: MISC EXPENSE | B39: =D39/$H$12 -> 0 | C39: =D39/12 -> 0 | D39: ='P&LY1'!O57 -> 0
A40: CASH BASED EXPENSE 1 | B40: =D40/$H$12 -> 0 | C40: =D40/12 -> 0 | D40: 0
A41: CASH BASED EXPENSE 2 | B41: =D41/$H$12 -> 0 | C41: =D41/12 -> 0 | D41: 0
A42: CASH BASED EXPENSE 3 | B42: =D42/$H$12 -> 0 | C42: =D42/12 -> 0 | D42: 0
A43: CASH BASED EXPENSE 4 | B43: =D43/$H$12 -> 0 | C43: =D43/12 -> 0 | D43: 0
A44: INTEREST EXPENSE | B44: =D44/$H$12 -> 0 | C44: =D44/12 -> 0 | D44: =SUM('P&LY1'!O62:O65) -> 0
...

Sheet Payroll Budget
A2: Daily Hours to Schedule by Month
C5: ='P&LY1'!C6 -> 44561 | D5: ='P&LY1'!D6 -> 44592 | E5: ='P&LY1'!E6 -> 44620 | F5: ='P&LY1'!F6 -> 44651 | G5: ='P&LY1'!G6 -> 44681 | H5: ='P&LY1'!H6 -> 44712 | I5: ='P&LY1'!I6 -> 44742 | J5: ='P&LY1'!J6 -> 44773 | ... N5: ='P&LY1'!N6 -> 44895
A7: Staff Hours Projection Based on P&LY1
A8: # of Weeks in Month | C8: =VLOOKUP(MONTH(C5),Input!$R$81:$T$92,3) -> 5 | D8: =VLOOKUP(MONTH(D5),Input!$R$81:$T$92,3) -> 4 | E8: =VLOOKUP(MONTH(E5),Input!$R$81:$T$92,3) -> 4 | F8: =VLOOKUP(MONTH(F5),Input!$R$81:$T$92,3) -> 5 | G8: =VLOOKUP(MONTH(G5),Input!$R$81:$T$92,3) -> 4 | H8: =VLOOKUP(MONTH(H5),Input!$R$81:$T$92,3) -> 4 | I8: =VLOOKUP(MONTH(I5),Input!$R$81:$T$92,3) -> 5 | J8: =VLOOKUP(MONTH(J5),Input!$R$81:$T$92,3) -> 4 | ... N8: =VLOOKUP(MONTH(N5),Input!$R$81:$T$92,3) -> 4
A10: Base Coverage (based on 140 hours minimum weekly) | C10: ='P&LY1'!C146 -> 700 | D10: ='P&LY1'!D146 -> 560 | E10: ='P&LY1'!E146 -> 560 | F10: ='P&LY1'!F146 -> 700 | G10: ='P&LY1'!G146 -> 560 | H10: ='P&LY1'!H146 -> 560 | I10: ='P&LY1'!I146 -> 700 | J10: ='P&LY1'!J146 -> 560 | ... N10: ='P&LY1'!N146 -> 560
A11: Variable Hours (based on sales index) | C11: ='P&LY1'!C147 -> #DIV/0! | D11: ='P&LY1'!D147 -> #DIV/0! | E11: ='P&LY1'!E147 -> #DIV/0! | F11: ='P&LY1'!F147 -> #DIV/0! | G11: ='P&LY1'!G147 -> #DIV/0! | H11: ='P&LY1'!H147 -> #DIV/0! | I11: ='P&LY1'!I147 -> #DIV/0! | J11: ='P&LY1'!J147 -> #DIV/0! | ... N11: ='P&LY1'!N147 -> #DIV/0!
A12: Subtotal Staff Hours by month | C12: ='P&LY1'!C148 -> #DIV/0! | D12: ='P&LY1'!D148 -> #DIV/0! | E12: ='P&LY1'!E148 -> #DIV/0! | F12: ='P&LY1'!F148 -> #DIV/0! | G12: ='P&LY1'!G148 -> #DIV/0! | H12: ='P&LY1'!H148 -> #DIV/0! | I12: ='P&LY1'!I148 -> #DIV/0! | J12: ='P&LY1'!J148 -> #DIV/0! | ... N12: ='P&LY1'!N148 -> #DIV/0!
A13: Franchisee/Manager Weekly Floor Hours | C13: =(Input!T27)/52 -> 0 | D13: =C13 -> 0 | E13: =D13 -> 0 | F13: =E13 -> 0 | G13: =F13 -> 0 | H13: =G13 -> 0 | I13: =H13 -> 0 | J13: =I13 -> 0 | K13: =J13 -> 0 | ... N13: =M13 -> 0
A14: Staff Hours Per Week | C14: =(C12/C8)-C13 -> #DIV/0! | D14: =(D12/D8)-D13 -> #DIV/0! | E14: =(E12/E8)-E13 -> #DIV/0! | F14: =(F12/F8)-F13 -> #DIV/0! | G14: =(G12/G8)-G13 -> #DIV/0! | H14: =(H12/H8)-H13 -> #DIV/0! | I14: =(I12/I8)-I13 -> #DIV/0! | J14: =(J12/J8)-J13 -> #DIV/0! | ... N14: =(N12/N8)-N13 -> #DIV/0!
A17: Daily Sales Index | B17: Sunday | C17: =Indices_Margins!B80 -> 0.14 | D17: =C17 -> 0.14 | E17: =D17 -> 0.14 | F17: =E17 -> 0.14 | G17: =F17 -> 0.14 | H17: =G17 -> 0.14 | I17: =H17 -> 0.14 | J17: =I17 -> 0.14 | K17: =J17 -> 0.14 | ... N17: =M17 -> 0.14
A18: Based on store's daily sales index | B18: Monday | C18: =Indices_Margins!B81 -> 0.11 | D18: =C18 -> 0.11 | E18: =D18 -> 0.11 | F18: =E18 -> 0.11 | G18: =F18 -> 0.11 | H18: =G18 -> 0.11 | I18: =H18 -> 0.11 | J18: =I18 -> 0.11 | K18: =J18 -> 0.11 | ... N18: =M18 -> 0.11
B19: Tuesday | C19: =Indices_Margins!B82 -> 0.1 | D19: =C19 -> 0.1 | E19: =D19 -> 0.1 | F19: =E19 -> 0.1 | G19: =F19 -> 0.1 | H19: =G19 -> 0.1 | I19: =H19 -> 0.1 | J19: =I19 -> 0.1 | K19: =J19 -> 0.1 | ... N19: =M19 -> 0.1
B20: Wednesday | C20: =Indices_Margins!B83 -> 0.11 | D20: =C20 -> 0.11 | E20: =D20 -> 0.11 | F20: =E20 -> 0.11 | G20: =F20 -> 0.11 | H20: =G20 -> 0.11 | I20: =H20 -> 0.11 | J20: =I20 -> 0.11 | K20: =J20 -> 0.11 | ... N20: =M20 -> 0.11
B21: Thursday | C21: =Indices_Margins!B84 -> 0.11 | D21: =C21 -> 0.11 | E21: =D21 -> 0.11 | F21: =E21 -> 0.11 | G21: =F21 -> 0.11 | H21: =G21 -> 0.11 | I21: =H21 -> 0.11 | J21: =I21 -> 0.11 | K21: =J21 -> 0.11 | ... N21: =M21 -> 0.11
B22: Friday | C22: =Indices_Margins!B85 -> 0.16 | D22: =C22 -> 0.16 | E22: =D22 -> 0.16 | F22: =E22 -> 0.16 | G22: =F22 -> 0.16 | H22: =G22 -> 0.16 | I22: =H22 -> 0.16 | J22: =I22 -> 0.16 | K22: =J22 -> 0.16 | ... N22: =M22 -> 0.16
B23: Saturday | C23: =Indices_Margins!B86 -> 0.23 | D23: =C23 -> 0.23 | E23: =D23 -> 0.23 | F23: =E23 -> 0.23 | G23: =F23 -> 0.23 | H23: =G23 -> 0.23 | I23: =H23 -> 0.23 | J23: =I23 -> 0.23 | K23: =J23 -> 0.23 | ... N23: =M23 -> 0.23
C26: =C5 -> 44561 | D26: =D5 -> 44592 | E26: =E5 -> 44620 | F26: =F5 -> 44651 | G26: =G5 -> 44681 | H26: =H5 -> 44712 | I26: =I5 -> 44742 | J26: =J5 -> 44773 | ... N26: =N5 -> 44895
A28: Hours to schedule each day/week | B28: Sunday | C28: =(C17*C14) -> #DIV/0! | D28: =(D17*D14) -> #DIV/0! | E28: =(E17*E14) -> #DIV/0! | F28: =(F17*F14) -> #DIV/0! | G28: =(G17*G14) -> #DIV/0! | H28: =(H17*H14) -> #DIV/0! | I28: =(I17*I14) -> #DIV/0! | J28: =(J17*J14) -> #DIV/0! | ... N28: =(N17*N14) -> #DIV/0!
B29: Monday | C29: =(C18*C14) -> #DIV/0! | D29: =(D18*D14) -> #DIV/0! | E29: =(E18*E14) -> #DIV/0! | F29: =(F18*F14) -> #DIV/0! | G29: =(G18*G14) -> #DIV/0! | H29: =(H18*H14) -> #DIV/0! | I29: =(I18*I14) -> #DIV/0! | J29: =(J18*J14) -> #DIV/0! | ... N29: =(N18*N14) -> #DIV/0!
B30: Tuesday | C30: =(C19*C14) -> #DIV/0! | D30: =(D19*D14) -> #DIV/0! | E30: =(E19*E14) -> #DIV/0! | F30: =(F19*F14) -> #DIV/0! | G30: =(G19*G14) -> #DIV/0! | H30: =(H19*H14) -> #DIV/0! | I30: =(I19*I14) -> #DIV/0! | J30: =(J19*J14) -> #DIV/0! | ... N30: =(N19*N14) -> #DIV/0!
B31: Wednesday | C31: =(C20*C14) -> #DIV/0! | D31: =(D20*D14) -> #DIV/0! | E31: =(E20*E14) -> #DIV/0! | F31: =(F20*F14) -> #DIV/0! | G31: =(G20*G14) -> #DIV/0! | H31: =(H20*H14) -> #DIV/0! | I31: =(I20*I14) -> #DIV/0! | J31: =(J20*J14) -> #DIV/0! | ... N31: =(N20*N14) -> #DIV/0!
B32: Thursday | C32: =(C21*C14) -> #DIV/0! | D32: =(D21*D14) -> #DIV/0! | E32: =(E21*E14) -> #DIV/0! | F32: =(F21*F14) -> #DIV/0! | G32: =(G21*G14) -> #DIV/0! | H32: =(H21*H14) -> #DIV/0! | I32: =(I21*I14) -> #DIV/0! | J32: =(J21*J14) -> #DIV/0! | ... N32: =(N21*N14) -> #DIV/0!
B33: Friday | C33: =(C22*C14) -> #DIV/0! | D33: =(D22*D14) -> #DIV/0! | E33: =(E22*E14) -> #DIV/0! | F33: =(F22*F14) -> #DIV/0! | G33: =(G22*G14) -> #DIV/0! | H33: =(H22*H14) -> #DIV/0! | I33: =(I22*I14) -> #DIV/0! | J33: =(J22*J14) -> #DIV/0! | ... N33: =(N22*N14) -> #DIV/0!
B34: Saturday | C34: =(C23*C14) -> #DIV/0! | D34: =(D23*D14) -> #DIV/0! | E34: =(E23*E14) -> #DIV/0! | F34: =(F23*F14) -> #DIV/0! | G34: =(G23*G14) -> #DIV/0! | H34: =(H23*H14) -> #DIV/0! | I34: =(I23*I14) -> #DIV/0! | J34: =(J23*J14) -> #DIV/0! | ... N34: =(N23*N14) -> #DIV/0!
B35: *Employee safety and event days need to be a consideration as above is a guideline
